<?xml version="1.0" encoding="utf-8"?>
<robot name="panda_simple">
  <link name="panda_link0">
    <visual>
      <geometry><box size="0.2 0.2 0.1"/></geometry>
    </visual>
  </link>

  <joint name="panda_joint1" type="revolute">
    <parent link="panda_link0"/>
    <child link="panda_link1"/>
    <axis xyz="0 0 1"/>
    <limit lower="-2.9" upper="2.9" velocity="3.0" effort="1000.0"/>
    <dynamics damping="0.0" friction="0.0"/>
  </joint>
  <link name="panda_link1">
    <inertial><mass value="0.5"/><inertia ixx="0.01" iyy="0.01" izz="0.01" ixy="0" ixz="0" iyz="0"/></inertial>
  </link>

  <joint name="panda_joint2" type="revolute">
    <parent link="panda_link1"/>
    <child link="panda_link2"/>
    <axis xyz="0 1 0"/>
    <limit lower="-2.9" upper="2.9" velocity="3.0" effort="1000.0"/>
    <dynamics damping="0.0" friction="0.0"/>
  </joint>
  <link name="panda_link2">
    <inertial><mass value="0.5"/><inertia ixx="0.01" iyy="0.01" izz="0.01" ixy="0" ixz="0" iyz="0"/></inertial>
  </link>

  <joint name="panda_joint3" type="revolute">
    <parent link="panda_link2"/>
    <child link="panda_link3"/>
    <axis xyz="0 1 0"/>
    <limit lower="-2.9" upper="2.9" velocity="3.0" effort="1000.0"/>
    <dynamics damping="0.0" friction="0.0"/>
  </joint>
  <link name="panda_link3">
    <inertial><mass value="0.5"/><inertia ixx="0.01" iyy="0.01" izz="0.01" ixy="0" ixz="0" iyz="0"/></inertial>
  </link>

  <joint name="panda_joint4" type="revolute">
    <parent link="panda_link3"/>
    <child link="panda_link4"/>
    <axis xyz="0 1 0"/>
    <limit lower="-2.9" upper="2.9" velocity="3.0" effort="1000.0"/>
    <dynamics damping="0.0" friction="0.0"/>
  </joint>
  <link name="panda_link4">
    <inertial><mass value="0.5"/><inertia ixx="0.01" iyy="0.01" izz="0.01" ixy="0" ixz="0" iyz="0"/></inertial>
  </link>

  <joint name="panda_joint5" type="revolute">
    <parent link="panda_link4"/>
    <child link="panda_link5"/>
    <axis xyz="0 1 0"/>
    <limit lower="-2.9" upper="2.9" velocity="3.0" effort="1000.0"/>
    <dynamics damping="0.0" friction="0.0"/>
  </joint>
  <link name="panda_link5">
    <inertial><mass value="0.5"/><inertia ixx="0.01" iyy="0.01" izz="0.01" ixy="0" ixz="0" iyz="0"/></inertial>
  </link>

  <joint name="panda_joint6" type="revolute">
    <parent link="panda_link5"/>
    <child link="panda_link6"/>
    <axis xyz="0 1 0"/>
    <limit lower="-2.9" upper="2.9" velocity="3.0" effort="1000.0"/>
    <dynamics damping="0.0" friction="0.0"/>
  </joint>
  <link name="panda_link6">
    <inertial><mass value="0.5"/><inertia ixx="0.01" iyy="0.01" izz="0.01" ixy="0" ixz="0" iyz="0"/></inertial>
  </link>

  <joint name="panda_joint7" type="fixed">
    <parent link="panda_link6"/>
    <child link="panda_link7"/>
  </joint>
  <link name="panda_link7">
    <visual><geometry><box size="0.05 0.05 0.05"/></geometry></visual>
  </link>
</robot>